Workbook
Name ABONUS_s.r.o.: 'databáza KONTAKTY'!$A$12:$A$169
Name producst: 'databáza KONTAKTY'!$B$1:$B$1
Name products: 'databáza KONTAKTY'!$B$1:$B$1

Sheet Výpis materiálu
D2: =D12 -> ZL-112-24-248 | F2: E.D.T. spol. s r.o., Galvaniho 4324/8, 821 04 Bratislava, Slovensko, IČO: 35 731 761, DIČ: 2020 251 343, IČ DPH: SK 2020 251 343
F3: Tel.: +421 2 43 42 29 51, e-mail: edt@edt.sk, www.edt.sk
F4: Bankové spojenie: Slovenská sporiteľňa, a.s., IBAN: SK97 0900 0000 0051 6609 4679
F5: Registrácia: OR Mestského súdu Bratislava III, oddiel Sro, vložka č.: 15919/B
F7: e-mail | I7: tel. číslo
C8: Zákazník: | D8: =CP!D19 -> 0
C9: V zastúpení: | D9: =CP!D20 -> 0 | F9: =CP!G20 -> 0 | I9: =CP!E20 -> 0
C10: Adresa: | D10: =CP!D21 -> 0
C11: Názov akcie: | D11: =CP!D22 -> Dodávka a montáž klimatizácie
C12: Číslo zákazky: | D12: =CP!D23 -> ZL-112-24-248
C13: Číslo ponuky: | D13: =CP!D24 -> CP-112-24-844
C14: Vybavuje: | D14: =CP!D26 -> Mgr. Martin Holík | F14: =CP!G26 -> 0 | I14: =CP!E26 -> 421902383121
C15: Dátum: | D15: =CP!D29 -> 45714
D16: Zoznam položiek
C18: Kód položky | D18: Popis položky | I18: Množstvo | J18: Merná jednotka
D22: =CP!#REF! -> #REF! | I22: =CP!#REF! -> #REF! | J22: =CP!#REF! -> #REF!
A23: 3 | B23: 3 | D23: =CP!#REF! -> #REF! | I23: =CP!#REF! -> #REF! | J23: =CP!#REF! -> #REF!
D24: =CP!#REF! -> #REF! | I24: =CP!#REF! -> #REF! | J24: =CP!#REF! -> #REF!
D25: =CP!#REF! -> #REF! | I25: =CP!#REF! -> #REF! | J25: =CP!#REF! -> #REF!
D26: =CP!#REF! -> #REF! | I26: =CP!#REF! -> #REF! | J26: =CP!#REF! -> #REF!
D27: =CP!#REF! -> #REF! | I27: =CP!#REF! -> #REF! | J27: =CP!#REF! -> #REF!
D28: =CP!#REF! -> #REF! | I28: =CP!#REF! -> #REF! | J28: =CP!#REF! -> #REF!
D29: =CP!#REF! -> #REF! | I29: =CP!#REF! -> #REF! | J29: =CP!#REF! -> #REF!
D30: =CP!#REF! -> #REF! | I30: =CP!#REF! -> #REF! | J30: =CP!#REF! -> #REF!
D31: =CP!#REF! -> #REF! | I31: =CP!#REF! -> #REF! | J31: =CP!#REF! -> #REF!
D32: =CP!#REF! -> #REF! | I32: =CP!#REF! -> #REF! | J32: =CP!#REF! -> #REF!
D33: =CP!#REF! -> #REF! | I33: =CP!#REF! -> #REF! | J33: =CP!#REF! -> #REF!
D34: =CP!#REF! -> #REF! | I34: =CP!#REF! -> #REF! | J34: =CP!#REF! -> #REF!
D35: =CP!#REF! -> #REF! | I35: =CP!#REF! -> #REF! | J35: =CP!#REF! -> #REF!
D36: =CP!D36 -> 0 | I36: =CP!F36 -> 1 | J36: =CP!E36 -> kpl
D37: =CP!D37 -> 0 | I37: =CP!F37 -> 1 | J37: =CP!E37 -> kpl
D38: =CP!D38 -> 0 | I38: =CP!F38 -> 1 | J38: =CP!E38 -> kpl
D39: =CP!D39 -> 0 | I39: =CP!F39 -> 1 | J39: =CP!E39 -> kpl
D40: =CP!D40 -> 0 | I40: =CP!F40 -> 1 | J40: =CP!E40 -> kpl
D41: =CP!D41 -> 0 | I41: =CP!F41 -> 1 | J41: =CP!E41 -> kpl
D42: =CP!D42 -> 0 | I42: =CP!F42 -> 1 | J42: =CP!E42 -> kpl
D43: =CP!D43 -> 0 | I43: =CP!F43 -> 1 | J43: =CP!E43 -> kpl
D44: =CP!D44 -> 0 | I44: =CP!F44 -> 1 | J44: =CP!E44 -> kpl
D45: =CP!D45 -> 0 | I45: =CP!F45 -> 1 | J45: =CP!E45 -> kpl
D46: =CP!D46 -> 0 | I46: =CP!F46 -> 1 | J46: =CP!E46 -> kpl
...

Sheet PP
B1: PREBERACÍ PROTOKOL | D1: označenie | E1: Q-F-3.13
D2: verzia | E2: 2
D3: platnosť od | E3: 29.02.2023
A5: Odovzdávajúci subjekt:
A7: Firma | C7: G.T LABS s.r.o
A8: ZASTÚPENIE / KONTAKT | C8: Mgr. Martin Holík | D8: =VLOOKUP(C8,'databáza KONTAKTY'!$B$1:$F$14,2,FALSE) -> 421902383121 | E8: =VLOOKUP(C8,'databáza KONTAKTY'!$B$1:$F$14,3,FALSE) -> holik@klimafresh.sk
A9: ADRESA | C9: Za mlynom 2, 83107 Bratislava - Vajnory
A10: IČO | C10: 53100972
A11: DIČ | C11: 2121276179
A12: Evidenčné číslo zákazky odovzdávajúceho subjektu | C12: =CP!D23 -> ZL-112-24-248
A14: Preberajúci subjekt: | C14: Spoločnosť Čínska reštaurácia, s.r.o.
A16: Firma | C16: Spoločnosť Čínska reštaurácia, s.r.o.
A17: ZASTÚPENIE / KONTAKT | C17: =CP!D20 -> 0 | D17: =CP!E20 -> 0 | E17: =CP!G20 -> 0
A18: ADRESA | C18: =CP!D21 -> 0
A19: IČO
A20: DIČ
A21: Evidenčné číslo preberacieho subjektu
A23: Hore uvedená firma týmto preberá nasledovný tovar / služby: | C23: 5x DJ35_G_COMFORT_3,5W_IDU | D23: 5x DJ35_W_COMFORT_3,5kW_ODU
A25: Číslo | B25: Tovar / služba | E25: Množstvo
A28: 1 | B28: =CP!D22 -> Dodávka a montáž klimatizácie | E28: 5ks
A32: Týmto hore uvedená firma prehlasuje, že prevzatý tovar/služby bol dodaný nepoškodený v plnom rozsahu v súlade s vystavenou objednávkou.
A34: Prevzatá hotovosť:
A46: =C8 -> Mgr. Martin Holík
A48: Čitateľné meno, pečiatka a podpis | D48: Čitateľné meno, pečiatka a podpis
A49: zástupcu odovzdávajúcej strany | D49: zástupcu preberajúcej strany
A51: V Bratislave, dňa:

Sheet CP
A1: 3 | B1: 1 | D1: hlavný nadpis
A2: 3 | B2: 2 | D2: podnadpis 1
A3: 3 | B3: 3 | D3: podnadpis 2 | E3: kpl | F3: 1000
D4: Hisense Easy CA25 Qch=2,6 kW vnútorná nástenná + vonkajšia | E4: =VLOOKUP(D4,cenniktoshiba!$B$3:$D121,3,FALSE) -> #N/A | F4: 1000 | G4: =H4/F4 -> #N/A | H4: =AK4 -> #N/A | I4: =AK4 -> #N/A | K4: =VLOOKUP(D4,cenniktoshiba!$B$3:$F121,5,FALSE) -> #N/A | L4: =VLOOKUP(D4,cenniktoshiba!$B$3:$C121,2,FALSE) -> #N/A | M4: =VLOOKUP(D4,cenniktoshiba!$B$3:$E121,4,FALSE) -> #N/A | N4: =L4*(1-M4) -> #N/A | O4: =N4*F4 -> #N/A | P4: 0,30 €/km | R4: {=_xlfn.IFS(P4=$P$28,$Q$28,P4=$P$26,Q4*$Q$26,P4=$P$27,Q4*$Q$27,P4=$P$25,Q4*$Q$25,P4=$P$29,$Q$29)} -> 0 | S4: =O4+R4 -> #N/A | T4: 1 | V4: 0 | X4: =IF(W4=$W$27,$X$27,0)+IF(W4=$W$28,$X$28,0)+IF(W4=$W$29,$X$29,0) -> 0 | Y4: =X4*U4*V4*T4 -> 0 | Z4: =Y4*F4 -> 0 | AA4: =S4+Z4 -> #N/A | AB4: =$AB$34 -> 0.3 | AC4: =$AC$34 -> 0.01 | AD4: =S4*AB4 -> #N/A | AE4: =Z4*AC4 -> 0 | AF4: =AD4+AE4 -> #N/A | AG4: =AA4+AF4 -> #N/A | AH4: =$AH$34/$Z$86*AA4 -> #N/A | AI4: =AG4+AH4 -> #N/A | AJ4: =$AJ$34/$AF$86*AF4 -> #N/A | AK4: =AI4+AJ4 -> #N/A | AM4: Powering | AN4: =IF(AM4="Powering",O4) -> #N/A | AO4: =$AO$34 -> 0.01 | AP4: =AN4*AO4 -> #N/A | AQ4: =AN4-AP4 -> #N/A
D5: MATERIÁL BEIJER ANMIMA | E5: =VLOOKUP(D5,'Cenník Beijer Anmima'!$B$3:$D$52,3,FALSE) -> #N/A | F5: 1000 | G5: =H5/F5 -> #N/A | H5: =AK5 -> #N/A | I5: =AK5 -> #N/A | K5: =VLOOKUP(D5,'Cenník Beijer Anmima'!$B$3:$G100,6,FALSE) -> #N/A | L5: =VLOOKUP(D5,'Cenník Beijer Anmima'!$B$2:$C$100,2,FALSE) -> #N/A | M5: 0 | N5: =L5*(1-M5) -> #N/A | O5: =N5*F5 -> #N/A | P5: 0,30 €/km | R5: {=_xlfn.IFS(P5=$P$28,$Q$28,P5=$P$26,Q5*$Q$26,P5=$P$27,Q5*$Q$27,P5=$P$25,Q5*$Q$25,P5=$P$29,$Q$29)} -> 0 | S5: =O5+R5 -> #N/A | T5: 1 | V5: 0 | X5: =IF(W5=$W$27,$X$27,0)+IF(W5=$W$28,$X$28,0)+IF(W5=$W$29,$X$29,0) -> 0 | Y5: =X5*U5*V5*T5 -> 0 | Z5: =Y5*F5 -> 0 | AA5: =S5+Z5 -> #N/A | AB5: =$AB$34 -> 0.3 | AC5: =$AC$34 -> 0.01 | AD5: =S5*AB5 -> #N/A | AE5: =Z5*AC5 -> 0 | AF5: =AD5+AE5 -> #N/A | AG5: =AA5+AF5 -> #N/A | AH5: =$AH$34/$Z$86*AA5 -> #N/A | AI5: =AG5+AH5 -> #N/A | AJ5: =$AJ$34/$AF$86*AF5 -> #N/A | AK5: =AI5+AJ5 -> #N/A | AN5: =IF(AM5="Powering",O5) -> FALSE | AO5: =$AO$34 -> 0.01 | AP5: =AN5*AO5 -> 0 | AQ5: =AN5-AP5 -> 0
D6: Konzola 450 mm s vodováhou (100 kg) | E6: =VLOOKUP(D6,'Cenník Sinclair '!$B$2:$D$43,3,FALSE) -> #N/A | F6: 1000 | G6: =H6/F6 -> #N/A | H6: =AK6 -> #N/A | I6: =AK6 -> #N/A | K6: =VLOOKUP(D6,'Cenník Sinclair '!$B$2:$F$101,5,FALSE) -> #N/A | L6: =VLOOKUP(D6,'Cenník Sinclair '!$B$2:$C$101,2,FALSE) -> #N/A | M6: =VLOOKUP(D6,'Cenník Sinclair '!$B$2:$E$101,4,FALSE) -> #N/A | N6: =L6*(1-M6) -> #N/A | O6: =N6*F6 -> #N/A | P6: 0,30 €/km | R6: {=_xlfn.IFS(P6=$P$28,$Q$28,P6=$P$26,Q6*$Q$26,P6=$P$27,Q6*$Q$27,P6=$P$25,Q6*$Q$25,P6=$P$29,$Q$29)} -> 0 | S6: =O6+R6 -> #N/A | T6: 1 | V6: 0 | X6: =IF(W6=$W$27,$X$27,0)+IF(W6=$W$28,$X$28,0)+IF(W6=$W$29,$X$29,0) -> 0 | Y6: =X6*U6*V6*T6 -> 0 | Z6: =Y6*F6 -> 0 | AA6: =S6+Z6 -> #N/A | AB6: =$AB$34 -> 0.3 | AC6: =$AC$34 -> 0.01 | AD6: =S6*AB6 -> #N/A | AE6: =Z6*AC6 -> 0 | AF6: =AD6+AE6 -> #N/A | AG6: =AA6+AF6 -> #N/A | AH6: =$AH$34/$Z$86*AA6 -> #N/A | AI6: =AG6+AH6 -> #N/A | AJ6: =$AJ$34/$AF$86*AF6 -> #N/A | AK6: =AI6+AJ6 -> #N/A | AN6: =IF(AM6="Powering",O6) -> FALSE | AO6: =$AO$34 -> 0.01 | AP6: =AN6*AO6 -> 0 | AQ6: =AN6-AP6 -> 0
D7: VIVAX | E7: =VLOOKUP(D7,'Cenník Sinclair '!$B$2:$D$43,3,FALSE) -> #N/A | F7: 1001 | G7: =H7/F7 -> #N/A | H7: =AK7 -> #N/A | I7: =AK7 -> #N/A | K7: =VLOOKUP(D7,'Cenník Sinclair '!$B$2:$F$101,5,FALSE) -> #N/A | L7: =VLOOKUP(D7,'Cenník Sinclair '!$B$2:$C$101,2,FALSE) -> #N/A | M7: =VLOOKUP(D7,'Cenník Sinclair '!$B$2:$E$101,4,FALSE) -> #N/A | N7: =L7*(1-M7) -> #N/A | O7: =N7*F7 -> #N/A | P7: 0,30 €/km | R7: {=_xlfn.IFS(P7=$P$28,$Q$28,P7=$P$26,Q7*$Q$26,P7=$P$27,Q7*$Q$27,P7=$P$25,Q7*$Q$25,P7=$P$29,$Q$29)} -> 0 | S7: =O7+R7 -> #N/A | T7: 1 | V7: 0 | X7: =IF(W7=$W$27,$X$27,0)+IF(W7=$W$28,$X$28,0)+IF(W7=$W$29,$X$29,0) -> 0 | Y7: =X7*U7*V7*T7 -> 0 | Z7: =Y7*F7 -> 0 | AA7: =S7+Z7 -> #N/A | AB7: =$AB$34 -> 0.3 | AC7: =$AC$34 -> 0.01 | AD7: =S7*AB7 -> #N/A | AE7: =Z7*AC7 -> 0 | AF7: =AD7+AE7 -> #N/A | AG7: =AA7+AF7 -> #N/A | AH7: =$AH$34/$Z$86*AA7 -> #N/A | AI7: =AG7+AH7 -> #N/A | AJ7: =$AJ$34/$AF$86*AF7 -> #N/A | AK7: =AI7+AJ7 -> #N/A | AN7: =IF(AM7="Powering",O7) -> FALSE | AO7: =$AO$34 -> 0.01 | AP7: =AN7*AO7 -> 0 | AQ7: =AN7-AP7 -> 0
D8: SINCLAIR | E8: =VLOOKUP(D8,'Cenník Sinclair '!$B$2:$D$43,3,FALSE) -> #N/A | F8: 1001 | G8: =H8/F8 -> #N/A | H8: =AK8 -> #N/A | I8: =AK8 -> #N/A | K8: =VLOOKUP(D8,'Cenník Sinclair '!$B$2:$F$101,5,FALSE) -> #N/A | L8: =VLOOKUP(D8,'Cenník Sinclair '!$B$2:$C$101,2,FALSE) -> #N/A | M8: =VLOOKUP(D8,'Cenník Sinclair '!$B$2:$E$101,4,FALSE) -> #N/A | N8: =L8*(1-M8) -> #N/A | O8: =N8*F8 -> #N/A | P8: 0,30 €/km | R8: {=_xlfn.IFS(P8=$P$28,$Q$28,P8=$P$26,Q8*$Q$26,P8=$P$27,Q8*$Q$27,P8=$P$25,Q8*$Q$25,P8=$P$29,$Q$29)} -> 0 | S8: =O8+R8 -> #N/A | T8: 1 | V8: 0 | X8: =IF(W8=$W$27,$X$27,0)+IF(W8=$W$28,$X$28,0)+IF(W8=$W$29,$X$29,0) -> 0 | Y8: =X8*U8*V8*T8 -> 0 | Z8: =Y8*F8 -> 0 | AA8: =S8+Z8 -> #N/A | AB8: =$AB$34 -> 0.3 | AC8: =$AC$34 -> 0.01 | AD8: =S8*AB8 -> #N/A | AE8: =Z8*AC8 -> 0 | AF8: =AD8+AE8 -> #N/A | AG8: =AA8+AF8 -> #N/A | AH8: =$AH$34/$Z$86*AA8 -> #N/A | AI8: =AG8+AH8 -> #N/A | AJ8: =$AJ$34/$AF$86*AF8 -> #N/A | AK8: =AI8+AJ8 -> #N/A | AN8: =IF(AM8="Powering",O8) -> FALSE | AO8: =$AO$34 -> 0.01 | AP8: =AN8*AO8 -> 0 | AQ8: =AN8-AP8 -> 0
A9: c | D9: MITSUBISHI | E9: =VLOOKUP(D9,'Cenník Mitsubishi'!$B$2:$D$116,3,FALSE) -> #N/A | F9: 1 | G9: =H9/F9 -> #N/A | H9: =AK9 -> #N/A | I9: =AK9 -> #N/A | K9: =VLOOKUP(D9,'Cenník Mitsubishi'!$B$2:$F$116,5,FALSE) -> #N/A | L9: =VLOOKUP(D9,'Cenník Mitsubishi'!$B$2:$F$116,2,FALSE) -> #N/A | M9: =VLOOKUP(D9,'Cenník Mitsubishi'!$B$2:$F$120,4,FALSE) -> #N/A | N9: =L9*(1-M9) -> #N/A | O9: =N9*F9 -> #N/A | P9: 0,30 €/km | R9: {=_xlfn.IFS(P9=$P$28,$Q$28,P9=$P$26,Q9*$Q$26,P9=$P$27,Q9*$Q$27,P9=$P$25,Q9*$Q$25,P9=$P$29,$Q$29)} -> 0 | S9: =O9+R9 -> #N/A | T9: 1 | V9: 0 | X9: =IF(W9=$W$27,$X$27,0)+IF(W9=$W$28,$X$28,0)+IF(W9=$W$29,$X$29,0) -> 0 | Y9: =X9*U9*V9*T9 -> 0 | Z9: =Y9*F9 -> 0 | AA9: =S9+Z9 -> #N/A | AB9: =$AB$34 -> 0.3 | AC9: =$AC$34 -> 0.01 | AD9: =S9*AB9 -> #N/A | AE9: =Z9*AC9 -> 0 | AF9: =AD9+AE9 -> #N/A | AG9: =AA9+AF9 -> #N/A | AH9: =$AH$34/$Z$86*AA9 -> #N/A | AI9: =AG9+AH9 -> #N/A | AJ9: =$AJ$34/$AF$86*AF9 -> #N/A | AK9: =AI9+AJ9 -> #N/A | AN9: =IF(AM9="Powering",O9) -> FALSE | AO9: =$AO$34 -> 0.01 | AP9: =AN9*AO9 -> 0 | AQ9: =AN9-AP9 -> 0
D10: TOSHIBA | E10: =VLOOKUP(D10,#REF!,3,FALSE) -> #REF! | F10: 1000 | G10: =H10/F10 -> #REF! | H10: =AK10 -> #REF! | I10: =AK10 -> #REF! | K10: =VLOOKUP(D10,#REF!,5,FALSE) -> #REF! | L10: =VLOOKUP(D10,#REF!,2,FALSE) -> #REF! | M10: =VLOOKUP(D10,#REF!,4,FALSE) -> #REF! | N10: =L10*(1-M10) -> #REF! | O10: =N10*F10 -> #REF! | P10: 0,30 €/km | R10: {=_xlfn.IFS(P10=$P$28,$Q$28,P10=$P$26,Q10*$Q$26,P10=$P$27,Q10*$Q$27,P10=$P$25,Q10*$Q$25,P10=$P$29,$Q$29)} -> 0 | S10: =O10+R10 -> #REF! | T10: 1 | V10: 0 | X10: =IF(W10=$W$27,$X$27,0)+IF(W10=$W$28,$X$28,0)+IF(W10=$W$29,$X$29,0) -> 0 | Y10: =X10*U10*V10*T10 -> 0 | Z10: =Y10*F10 -> 0 | AA10: =S10+Z10 -> #REF! | AB10: =$AB$34 -> 0.3 | AC10: =$AC$34 -> 0.01 | AD10: =S10*AB10 -> #REF! | AE10: =Z10*AC10 -> 0 | AF10: =AD10+AE10 -> #REF! | AG10: =AA10+AF10 -> #REF! | AH10: =$AH$34/$Z$86*AA10 -> #N/A | AI10: =AG10+AH10 -> #REF! | AJ10: =$AJ$34/$AF$86*AF10 -> #N/A | AK10: =AI10+AJ10 -> #REF! | AN10: =IF(AM10="Powering",O10) -> FALSE | AO10: =$AO$34 -> 0.01 | AP10: =AN10*AO10 -> 0 | AQ10: =AN10-AP10 -> 0
D11: PANASONIC | E11: =VLOOKUP(D11,#REF!,3,FALSE) -> #REF! | F11: 1000 | G11: =H11/F11 -> #REF! | H11: =AK11 -> #REF! | I11: =AK11 -> #REF! | K11: =VLOOKUP(D11,#REF!,5,FALSE) -> #REF! | L11: =VLOOKUP(D11,#REF!,2,FALSE) -> #REF! | M11: =VLOOKUP(D11,#REF!,4,FALSE) -> #REF! | N11: =L11*(1-M11) -> #REF! | O11: =N11*F11 -> #REF! | P11: 0,30 €/km | R11: {=_xlfn.IFS(P11=$P$28,$Q$28,P11=$P$26,Q11*$Q$26,P11=$P$27,Q11*$Q$27,P11=$P$25,Q11*$Q$25,P11=$P$29,$Q$29)} -> 0 | S11: =O11+R11 -> #REF! | T11: 1 | V11: 0 | X11: =IF(W11=$W$27,$X$27,0)+IF(W11=$W$28,$X$28,0)+IF(W11=$W$29,$X$29,0) -> 0 | Y11: =X11*U11*V11*T11 -> 0 | Z11: =Y11*F11 -> 0 | AA11: =S11+Z11 -> #REF! | AB11: =$AB$34 -> 0.3 | AC11: =$AC$34 -> 0.01 | AD11: =S11*AB11 -> #REF! | AE11: =Z11*AC11 -> 0 | AF11: =AD11+AE11 -> #REF! | AG11: =AA11+AF11 -> #REF! | AH11: =$AH$34/$Z$86*AA11 -> #N/A | AI11: =AG11+AH11 -> #REF! | AJ11: =$AJ$34/$AF$86*AF11 -> #N/A | AK11: =AI11+AJ11 -> #REF! | AN11: =IF(AM11="Powering",O11) -> FALSE | AO11: =$AO$34 -> 0.01 | AP11: =AN11*AO11 -> 0 | AQ11: =AN11-AP11 -> 0
C17: CP-112-24-844 | E17: GT Labs s.r.o. IČO 53100972 DIČ 2121276179IČ DPHSK2121276179, podľa §4, registrácia od 5.11.2022 Sídlo GT LABS, s.r.o. Za mlynom 2 831 07 Bratislava - mestská časť Vajnory
E18: tel. číslo | G18: e-mail
C19: Zákazník: | E19: 421910950582 | I19: mgr.peterlani@gmail.com
C20: V zastúpení:
C21: Adresa:
C22: Názov akcie: | D22: Dodávka a montáž klimatizácie
C23: Číslo zákazky: | D23: ZL-112-24-248
C24: Číslo ponuky: | D24: CP-112-24-844 | L24: ZĽAVA | P24: DOPRAVA | Q24: €/km
C25: Revízia: | D25: R1 | L25: Hisense | M25: 0.52 | P25: 0,30 €/km | Q25: 0.3 | W25: MONTÁŽNICI
C26: Vybavuje: | D26: Mgr. Martin Holík | E26: =VLOOKUP(D26,'databáza KONTAKTY'!$B$1:$F$10,2,FALSE) -> 421902383121 | L26: Powering | M26: 0.5 | P26: 0,50 €/km | Q26: 0.5 | W26: Typ | X26: Eur/hod
C27: Vypracoval: | D27: Mgr. Martin Holík | E27: =VLOOKUP(D27,'databáza KONTAKTY'!$B$1:$F$10,2,FALSE) -> 421902383121 | P27: 0,70 €/km | Q27: 0.7 | W27: Technik | X27: 22
C28: Schválil | D28: Mgr. Martin Holík | E28: =VLOOKUP(D28,'databáza KONTAKTY'!$B$1:$F$10,2,FALSE) -> 421902383121 | L28: PRÍPLATOK | P28: Suma 1 | Q28: 10 | W28: MaR | X28: 35
C29: Dátum: | D29: =TODAY() -> 45714 | L29: Tvarovky | M29: 0.3 | P29: Suma 2 | Q29: 15 | W29: Dozor | X29: 25
D30: Cenotvorba
K31: NÁKLADY | AB31: ZISK | AG31: VÝSLEDNÁ CENA | AM31: ZĽAVA NA PROJEKT - POWERING
C32: Kód položky | D32: Popis položky | E32: Merná jednotka | F32: Množstvo | G32: Jednotková cena | H32: Cena spolu | I32: Cena spolu | K32: DODÁVKA | T32: MONTÁŽ | AA32: NÁKLAD SPOLU | AB32: MARŽA | AD32: ZISK | AG32: ROZPUSTENÉ | AK32: KONEČNÁ CENA
K33: NÁKUP | P33: DOPRAVA | S33: Dodávka spolu | T33: Počet dní | U33: Počet hodín | V33: Počet ľudí | W33: Typ montáž-nika | X33: Hodinovka | Y33: Jedn. cena montáž | Z33: Montáž spolu | AB33: Dodávka | AC33: Montáž | AD33: Dodávka | AE33: Montáž | AF33: ZISK SPOLU | AG33: Rozpustený náklad | AI33: Rozpustený zisk | AM33: Dodávateľ | AN33: Pôvodná nákupná cena | AO33: Zľava | AP33: Suma zľavy | AQ33: Zľavnená nákupná cena
K34: Dodávateľ | L34: Jednotková cena | M34: zľava (%) | N34: Jedn. cena po zľave | O34: Nákup spolu | P34: Typ dopravy | Q34: Počet km spolu | R34: Doprava spolu | AB34: 0.3 | AC34: 0.01 | AG34: Náklad + zisk | AH34: 0 | AI34: Náklad + zisk + rozp. náklad | AJ34: 0 | AO34: 0.01
E36: kpl | F36: 1 | G36: =H36/F36 -> #N/A | H36: =AK36 -> #N/A | I36: 0 | N36: =L36*(1-M36) -> 0 | O36: =N36*F36 -> 0 | P36: 0,30 €/km | R36: {=_xlfn.IFS(P36=$P$28,$Q$28,P36=$P$26,Q36*$Q$26,P36=$P$27,Q36*$Q$27,P36=$P$25,Q36*$Q$25,P36=$P$29,$Q$29)} -> 0 | S36: =O36+R36 -> 0 | T36: 1 | V36: 0 | X36: =IF(W36=$W$27,$X$27,0)+IF(W36=$W$28,$X$28,0)+IF(W36=$W$29,$X$29,0) -> 0 | Y36: =X36*U36*V36*T36 -> 0 | Z36: =Y36*F36 -> 0 | AA36: =S36+Z36 -> 0 | AB36: 0.43 | AC36: =$AC$34 -> 0.01 | AD36: =S36*AB36 -> 0 | AE36: =Z36*AC36 -> 0 | AF36: =AD36+AE36 -> 0 | AG36: =AA36+AF36 -> 0 | AH36: =$AH$34/$Z$86*AA36 -> #N/A | AI36: =AG36+AH36 -> #N/A | AJ36: =$AJ$34/$AF$86*AF36 -> #N/A | AK36: =AI36+AJ36 -> #N/A | AN36: =IF(AM36="Powering",O36) -> FALSE | AO36: =$AO$34 -> 0.01 | AP36: =AN36*AO36 -> 0 | AQ36: =AN36-AP36 -> 0
E37: kpl | F37: 1 | G37: =H37/F37 -> #N/A | H37: =AK37 -> #N/A | I37: 0 | N37: =L37*(1-M37) -> 0 | O37: =N37*F37 -> 0 | P37: 0,30 €/km | R37: {=_xlfn.IFS(P37=$P$28,$Q$28,P37=$P$26,Q37*$Q$26,P37=$P$27,Q37*$Q$27,P37=$P$25,Q37*$Q$25,P37=$P$29,$Q$29)} -> 0 | S37: =O37+R37 -> 0 | T37: 1 | V37: 0 | X37: =IF(W37=$W$27,$X$27,0)+IF(W37=$W$28,$X$28,0)+IF(W37=$W$29,$X$29,0) -> 0 | Y37: =X37*U37*V37*T37 -> 0 | Z37: =Y37*F37 -> 0 | AA37: =S37+Z37 -> 0 | AB37: 0.43 | AC37: =$AC$34 -> 0.01 | AD37: =S37*AB37 -> 0 | AE37: =Z37*AC37 -> 0 | AF37: =AD37+AE37 -> 0 | AG37: =AA37+AF37 -> 0 | AH37: =$AH$34/$Z$86*AA37 -> #N/A | AI37: =AG37+AH37 -> #N/A | AJ37: =$AJ$34/$AF$86*AF37 -> #N/A | AK37: =AI37+AJ37 -> #N/A | AN37: =IF(AM37="Powering",O37) -> FALSE | AO37: =$AO$34 -> 0.01 | AP37: =AN37*AO37 -> 0 | AQ37: =AN37-AP37 -> 0
E38: kpl | F38: 1 | G38: =H38/F38 -> #N/A | H38: =AK38 -> #N/A | I38: 0 | N38: =L38*(1-M38) -> 0 | O38: =N38*F38 -> 0 | P38: 0,30 €/km | R38: {=_xlfn.IFS(P38=$P$28,$Q$28,P38=$P$26,Q38*$Q$26,P38=$P$27,Q38*$Q$27,P38=$P$25,Q38*$Q$25,P38=$P$29,$Q$29)} -> 0 | S38: =O38+R38 -> 0 | T38: 1 | V38: 0 | X38: =IF(W38=$W$27,$X$27,0)+IF(W38=$W$28,$X$28,0)+IF(W38=$W$29,$X$29,0) -> 0 | Y38: =X38*U38*V38*T38 -> 0 | Z38: =Y38*F38 -> 0 | AA38: =S38+Z38 -> 0 | AB38: 0.43 | AC38: =$AC$34 -> 0.01 | AD38: =S38*AB38 -> 0 | AE38: =Z38*AC38 -> 0 | AF38: =AD38+AE38 -> 0 | AG38: =AA38+AF38 -> 0 | AH38: =$AH$34/$Z$86*AA38 -> #N/A | AI38: =AG38+AH38 -> #N/A | AJ38: =$AJ$34/$AF$86*AF38 -> #N/A | AK38: =AI38+AJ38 -> #N/A | AN38: =IF(AM38="Powering",O38) -> FALSE | AO38: =$AO$34 -> 0.01 | AP38: =AN38*AO38 -> 0 | AQ38: =AN38-AP38 -> 0
E39: kpl | F39: 1 | G39: =H39/F39 -> #N/A | H39: =AK39 -> #N/A | I39: 0 | N39: =L39*(1-M39) -> 0 | O39: =N39*F39 -> 0 | P39: 0,30 €/km | R39: {=_xlfn.IFS(P39=$P$28,$Q$28,P39=$P$26,Q39*$Q$26,P39=$P$27,Q39*$Q$27,P39=$P$25,Q39*$Q$25,P39=$P$29,$Q$29)} -> 0 | S39: =O39+R39 -> 0 | T39: 1 | V39: 0 | X39: =IF(W39=$W$27,$X$27,0)+IF(W39=$W$28,$X$28,0)+IF(W39=$W$29,$X$29,0) -> 0 | Y39: =X39*U39*V39*T39 -> 0 | Z39: =Y39*F39 -> 0 | AA39: =S39+Z39 -> 0 | AB39: 0.43 | AC39: =$AC$34 -> 0.01 | AD39: =S39*AB39 -> 0 | AE39: =Z39*AC39 -> 0 | AF39: =AD39+AE39 -> 0 | AG39: =AA39+AF39 -> 0 | AH39: =$AH$34/$Z$86*AA39 -> #N/A | AI39: =AG39+AH39 -> #N/A | AJ39: =$AJ$34/$AF$86*AF39 -> #N/A | AK39: =AI39+AJ39 -> #N/A | AN39: =IF(AM39="Powering",O39) -> FALSE | AO39: =$AO$34 -> 0.01 | AP39: =AN39*AO39 -> 0 | AQ39: =AN39-AP39 -> 0
E40: kpl | F40: 1 | G40: =H40/F40 -> #N/A | H40: =AK40 -> #N/A | I40: 0 | N40: =L40*(1-M40) -> 0 | O40: =N40*F40 -> 0 | P40: 0,30 €/km | R40: {=_xlfn.IFS(P40=$P$28,$Q$28,P40=$P$26,Q40*$Q$26,P40=$P$27,Q40*$Q$27,P40=$P$25,Q40*$Q$25,P40=$P$29,$Q$29)} -> 0 | S40: =O40+R40 -> 0 | T40: 1 | V40: 0 | X40: =IF(W40=$W$27,$X$27,0)+IF(W40=$W$28,$X$28,0)+IF(W40=$W$29,$X$29,0) -> 0 | Y40: =X40*U40*V40*T40 -> 0 | Z40: =Y40*F40 -> 0 | AA40: =S40+Z40 -> 0 | AB40: 0.43 | AC40: =$AC$34 -> 0.01 | AD40: =S40*AB40 -> 0 | AE40: =Z40*AC40 -> 0 | AF40: =AD40+AE40 -> 0 | AG40: =AA40+AF40 -> 0 | AH40: =$AH$34/$Z$86*AA40 -> #N/A | AI40: =AG40+AH40 -> #N/A | AJ40: =$AJ$34/$AF$86*AF40 -> #N/A | AK40: =AI40+AJ40 -> #N/A | AN40: =IF(AM40="Powering",O40) -> FALSE | AO40: =$AO$34 -> 0.01 | AP40: =AN40*AO40 -> 0 | AQ40: =AN40-AP40 -> 0
E41: kpl | F41: 1 | G41: =H41/F41 -> #N/A | H41: =AK41 -> #N/A | I41: 0 | N41: =L41*(1-M41) -> 0 | O41: =N41*F41 -> 0 | P41: 0,30 €/km | R41: {=_xlfn.IFS(P41=$P$28,$Q$28,P41=$P$26,Q41*$Q$26,P41=$P$27,Q41*$Q$27,P41=$P$25,Q41*$Q$25,P41=$P$29,$Q$29)} -> 0 | S41: =O41+R41 -> 0 | T41: 1 | V41: 0 | X41: =IF(W41=$W$27,$X$27,0)+IF(W41=$W$28,$X$28,0)+IF(W41=$W$29,$X$29,0) -> 0 | Y41: =X41*U41*V41*T41 -> 0 | Z41: =Y41*F41 -> 0 | AA41: =S41+Z41 -> 0 | AB41: 0.43 | AC41: =$AC$34 -> 0.01 | AD41: =S41*AB41 -> 0 | AE41: =Z41*AC41 -> 0 | AF41: =AD41+AE41 -> 0 | AG41: =AA41+AF41 -> 0 | AH41: =$AH$34/$Z$86*AA41 -> #N/A | AI41: =AG41+AH41 -> #N/A | AJ41: =$AJ$34/$AF$86*AF41 -> #N/A | AK41: =AI41+AJ41 -> #N/A | AN41: =IF(AM41="Powering",O41) -> FALSE | AO41: =$AO$34 -> 0.01 | AP41: =AN41*AO41 -> 0 | AQ41: =AN41-AP41 -> 0
E42: kpl | F42: 1 | G42: =H42/F42 -> #N/A | H42: =AK42 -> #N/A | I42: 0 | N42: =L42*(1-M42) -> 0 | O42: =N42*F42 -> 0 | P42: 0,30 €/km | R42: {=_xlfn.IFS(P42=$P$28,$Q$28,P42=$P$26,Q42*$Q$26,P42=$P$27,Q42*$Q$27,P42=$P$25,Q42*$Q$25,P42=$P$29,$Q$29)} -> 0 | S42: =O42+R42 -> 0 | T42: 1 | V42: 0 | X42: =IF(W42=$W$27,$X$27,0)+IF(W42=$W$28,$X$28,0)+IF(W42=$W$29,$X$29,0) -> 0 | Y42: =X42*U42*V42*T42 -> 0 | Z42: =Y42*F42 -> 0 | AA42: =S42+Z42 -> 0 | AB42: 0.43 | AC42: =$AC$34 -> 0.01 | AD42: =S42*AB42 -> 0 | AE42: =Z42*AC42 -> 0 | AF42: =AD42+AE42 -> 0 | AG42: =AA42+AF42 -> 0 | AH42: =$AH$34/$Z$86*AA42 -> #N/A | AI42: =AG42+AH42 -> #N/A | AJ42: =$AJ$34/$AF$86*AF42 -> #N/A | AK42: =AI42+AJ42 -> #N/A | AN42: =IF(AM42="Powering",O42) -> FALSE | AO42: =$AO$34 -> 0.01 | AP42: =AN42*AO42 -> 0 | AQ42: =AN42-AP42 -> 0
E43: kpl | F43: 1 | G43: =H43/F43 -> #N/A | H43: =AK43 -> #N/A | I43: 0 | N43: =L43*(1-M43) -> 0 | O43: =N43*F43 -> 0 | P43: 0,30 €/km | R43: {=_xlfn.IFS(P43=$P$28,$Q$28,P43=$P$26,Q43*$Q$26,P43=$P$27,Q43*$Q$27,P43=$P$25,Q43*$Q$25,P43=$P$29,$Q$29)} -> 0 | S43: =O43+R43 -> 0 | T43: 1 | V43: 0 | X43: =IF(W43=$W$27,$X$27,0)+IF(W43=$W$28,$X$28,0)+IF(W43=$W$29,$X$29,0) -> 0 | Y43: =X43*U43*V43*T43 -> 0 | Z43: =Y43*F43 -> 0 | AA43: =S43+Z43 -> 0 | AB43: 0.43 | AC43: =$AC$34 -> 0.01 | AD43: =S43*AB43 -> 0 | AE43: =Z43*AC43 -> 0 | AF43: =AD43+AE43 -> 0 | AG43: =AA43+AF43 -> 0 | AH43: =$AH$34/$Z$86*AA43 -> #N/A | AI43: =AG43+AH43 -> #N/A | AJ43: =$AJ$34/$AF$86*AF43 -> #N/A | AK43: =AI43+AJ43 -> #N/A | AN43: =IF(AM43="Powering",O43) -> FALSE | AO43: =$AO$34 -> 0.01 | AP43: =AN43*AO43 -> 0 | AQ43: =AN43-AP43 -> 0
E44: kpl | F44: 1 | G44: =H44/F44 -> #N/A | H44: =AK44 -> #N/A | I44: 0 | N44: =L44*(1-M44) -> 0 | O44: =N44*F44 -> 0 | P44: 0,30 €/km | R44: {=_xlfn.IFS(P44=$P$28,$Q$28,P44=$P$26,Q44*$Q$26,P44=$P$27,Q44*$Q$27,P44=$P$25,Q44*$Q$25,P44=$P$29,$Q$29)} -> 0 | S44: =O44+R44 -> 0 | T44: 1 | V44: 0 | X44: =IF(W44=$W$27,$X$27,0)+IF(W44=$W$28,$X$28,0)+IF(W44=$W$29,$X$29,0) -> 0 | Y44: =X44*U44*V44*T44 -> 0 | Z44: =Y44*F44 -> 0 | AA44: =S44+Z44 -> 0 | AB44: 0.43 | AC44: =$AC$34 -> 0.01 | AD44: =S44*AB44 -> 0 | AE44: =Z44*AC44 -> 0 | AF44: =AD44+AE44 -> 0 | AG44: =AA44+AF44 -> 0 | AH44: =$AH$34/$Z$86*AA44 -> #N/A | AI44: =AG44+AH44 -> #N/A | AJ44: =$AJ$34/$AF$86*AF44 -> #N/A | AK44: =AI44+AJ44 -> #N/A | AN44: =IF(AM44="Powering",O44) -> FALSE | AO44: =$AO$34 -> 0.01 | AP44: =AN44*AO44 -> 0 | AQ44: =AN44-AP44 -> 0
E45: kpl | F45: 1 | G45: =H45/F45 -> #N/A | H45: =AK45 -> #N/A | I45: 0 | N45: =L45*(1-M45) -> 0 | O45: =N45*F45 -> 0 | P45: 0,30 €/km | R45: {=_xlfn.IFS(P45=$P$28,$Q$28,P45=$P$26,Q45*$Q$26,P45=$P$27,Q45*$Q$27,P45=$P$25,Q45*$Q$25,P45=$P$29,$Q$29)} -> 0 | S45: =O45+R45 -> 0 | T45: 1 | V45: 0 | X45: =IF(W45=$W$27,$X$27,0)+IF(W45=$W$28,$X$28,0)+IF(W45=$W$29,$X$29,0) -> 0 | Y45: =X45*U45*V45*T45 -> 0 | Z45: =Y45*F45 -> 0 | AA45: =S45+Z45 -> 0 | AB45: 0.43 | AC45: =$AC$34 -> 0.01 | AD45: =S45*AB45 -> 0 | AE45: =Z45*AC45 -> 0 | AF45: =AD45+AE45 -> 0 | AG45: =AA45+AF45 -> 0 | AH45: =$AH$34/$Z$86*AA45 -> #N/A | AI45: =AG45+AH45 -> #N/A | AJ45: =$AJ$34/$AF$86*AF45 -> #N/A | AK45: =AI45+AJ45 -> #N/A | AN45: =IF(AM45="Powering",O45) -> FALSE | AO45: =$AO$34 -> 0.01 | AP45: =AN45*AO45 -> 0 | AQ45: =AN45-AP45 -> 0
E46: kpl | F46: 1 | G46: =H46/F46 -> #N/A | H46: =AK46 -> #N/A | I46: 0 | N46: =L46*(1-M46) -> 0 | O46: =N46*F46 -> 0 | P46: 0,30 €/km | R46: {=_xlfn.IFS(P46=$P$28,$Q$28,P46=$P$26,Q46*$Q$26,P46=$P$27,Q46*$Q$27,P46=$P$25,Q46*$Q$25,P46=$P$29,$Q$29)} -> 0 | S46: =O46+R46 -> 0 | T46: 1 | V46: 0 | X46: =IF(W46=$W$27,$X$27,0)+IF(W46=$W$28,$X$28,0)+IF(W46=$W$29,$X$29,0) -> 0 | Y46: =X46*U46*V46*T46 -> 0 | Z46: =Y46*F46 -> 0 | AA46: =S46+Z46 -> 0 | AB46: 0.43 | AC46: =$AC$34 -> 0.01 | AD46: =S46*AB46 -> 0 | AE46: =Z46*AC46 -> 0 | AF46: =AD46+AE46 -> 0 | AG46: =AA46+AF46 -> 0 | AH46: =$AH$34/$Z$86*AA46 -> #N/A | AI46: =AG46+AH46 -> #N/A | AJ46: =$AJ$34/$AF$86*AF46 -> #N/A | AK46: =AI46+AJ46 -> #N/A | AN46: =IF(AM46="Powering",O46) -> FALSE | AO46: =$AO$34 -> 0.01 | AP46: =AN46*AO46 -> 0 | AQ46: =AN46-AP46 -> 0
...

Sheet Cenník Beijer Anmima
A1: P.č. | B1: MATERIÁL BEIJER ANMIMA | C1: Cenník | D1: Jednotka | E1: Cena z | F1: Aktualizované | G1: Dodávateľ
A2: 1 | B2: =IF($H$3>0,"Žľab 60x45 mm + tvarovky","Žľab 60x45 mm") -> Žľab 60x45 mm + tvarovky | C2: =2.2*(1+$H$3) -> 2.86 | D2: m | E2: 45331 | F2: 45331 | G2: Beijer | H2: Príplatok tvarovky
A3: 2 | B3: =IF($H$3>0,"Žľab 80x60 mm + tvarovky","Žľab 80x60 mm") -> Žľab 80x60 mm + tvarovky | C3: =3.3*(1+$H$3) -> 4.29 | D3: m | E3: 45331 | F3: 45331 | G3: Beijer | H3: =CP!M29 -> 0.3
A4: 3 | B4: =IF($H$3>0,"Žľab 110x75 mm + tvarovky","Žľab 110x75 mm") -> Žľab 110x75 mm + tvarovky | C4: =4.7*(1+$H$3) -> 6.11 | D4: m | E4: 45331 | F4: 45331 | G4: Beijer
A5: 4 | B5: Potrubie Cu 6/10 x 0,8 Dual | C5: 4.15 | D5: m | E5: 45331 | F5: 45331 | G5: Beijer
A6: 5 | B6: Potrubie Cu 6/12 x 0,8 Dual | C6: 5.25 | D6: m | E6: 45331 | F6: 45331 | G6: Beijer
A7: 6 | B7: Potrubie Cu 10/16 x 0,8 Dual | C7: 8.9 | D7: m | E7: 45405 | F7: 45405 | G7: Beijer
A8: 7 | B8: Potrubie Cu 6 x 0,8 Single | C8: 1.65 | D8: m | E8: 45331 | F8: 45331 | G8: Beijer
A9: 8 | B9: Potrubie Cu 10 x 0,8 Single | C9: 2.5 | D9: m | E9: 45331 | F9: 45331 | G9: Beijer
A10: 9 | B10: Potrubie Cu 12 x 0,8 Single | C10: 3.45 | D10: m | E10: 45331 | F10: 45331 | G10: Beijer
A11: 10 | B11: Potrubie Cu 16 x 1,0 Single | C11: 5.5 | D11: m | E11: 45331 | F11: 45331 | G11: Beijer
A12: 11 | B12: Potrubie Cu 22 x 1,0 Single | C12: 9.3 | D12: m | E12: 45331 | F12: 45331 | G12: Beijer
A13: 12 | B13: Hadica na kondenz 16 mm | C13: 0.48 | D13: m | E13: 45225 | F13: 45271 | G13: Beijer
A14: 13 | B14: Hadica na kondenz 20 mm | C14: 0.54 | D14: m | E14: 45238 | F14: 45271 | G14: Beijer
A15: 14 | B15: Spojka na hadicu 16 mm | C15: 1 | D15: ks | E15: 45159 | F15: 45271 | G15: Beijer
A16: 15 | B16: Kábel CYSY 3x1,5 | C16: 0.57 | D16: m | E16: 45133 | F16: 45271 | G16: Anmima
A17: 16 | B17: Kábel CYSY 3x2,5 | C17: 0.96 | D17: m | E17: 45125 | F17: 45271 | G17: Anmima
A18: 17 | B18: Kábel CYSY 3x4 | C18: 1.66 | D18: m | E18: 45306 | F18: 45306 | G18: Anmima | I18: https://www.aktaon.com/vodic-cysy-3x4-0-h05vv-f-p16515
A19: 18 | B19: Kábel CYSY 3x6 | C19: 3.33 | D19: m | E19: 45306 | F19: 45306 | G19: Anmima | I19: https://www.aktaon.com/vodic-cysy-3x6-0-h05vv-f-p16516
A20: 19 | B20: Kábel CYSY 5x2,5 | C20: 1.75 | D20: m | E20: 45306 | F20: 45306 | G20: Anmima | I20: https://www.aktaon.com/vodic-cysy-5x2-5-h05vv-f-p16529
A21: 20 | B21: Kábel CYKY-J 5x1,5 | C21: 0.78 | D21: m | E21: 45195 | F21: 45271 | G21: Anmima
A22: 21 | B22: Kábel CYKY-J 5x2,5 | C22: 1.49 | D22: m | E22: 45033 | F22: 45306 | G22: Anmima
A23: 22 | B23: Kábel JY(St)Y 1x2x0,8 | C23: 0.26 | D23: m | E23: 45264 | F23: 45271 | G23: Anmima
A24: 23 | B24: Kábel JY(St)Y 2x2x0,8 | C24: 0.36 | D24: m | E24: 45236 | F24: 45303 | G24: Anmima
A25: 24 | B25: Istič LTE 16C/1 6 kA (16 A) | C25: 4.26 | D25: ks | E25: 45035 | F25: 45303 | G25: Anmima
A26: 25 | B26: Istič LTE 20C/1 6 kA (20 A) | C26: 5.95 | D26: ks | E26: 45306 | F26: 45306 | G26: Anmima | I26: https://www.elektro-sychra.sk/istic-lte-20c-1-p789/
A27: 26 | B27: Istič LTE 25C/1 6 kA (25 A) | C27: 6.8 | D27: ks | E27: 45306 | F27: 45306 | G27: Anmima | I27: https://www.elektro-sychra.sk/oez-lte-25c-1-p6187/
A28: 27 | B28: Istič LTN 32C/1 6 kA (32 A) | C28: 11.57 | D28: ks | E28: 45306 | F28: 45306 | G28: Anmima | I28: https://www.elektro-sychra.sk/istic-ltn-32c-1-p801/
A29: 28 | B29: Istič LTE 16C/3 6 kA (16 A) | C29: 16.29 | D29: ks | E29: 45306 | F29: 45306 | G29: Anmima | I29: https://www.elektro-sychra.sk/istic-lte-16c-3-p849/
A30: 29 | B30: Istič LTE 32C/3 6 kA (32 A) | C30: 23.23 | D30: ks | E30: 45306 | F30: 45306 | G30: Anmima
A31: 30 | B31: Lišta LHD 20x20 mm | C31: 0.65 | D31: m | E31: 45223 | F31: 45271 | G31: Anmima
A32: 31 | B32: Lišta LHD 30x30 mm | C32: 0.77 | D32: m | E32: 45239 | F32: 45271 | G32: Anmima
A33: 32 | B33: Vidlica lomená | C33: 1.16 | D33: ks | E33: 45195 | F33: 45271 | G33: Anmima
A34: 33 | B34: Chladivo R32 | C34: 24 | D34: kg | E34: 45457 | F34: =E34 -> 45457 | G34: Beijer
A35: 34 | B35: Chladivo R410A | C35: 45 | D35: kg | E35: 45335 | F35: 45457 | G35: Beijer
A36: 35 | B36: Konzola na zem SP740 biela do 200 kg | C36: 29 | D36: ks | E36: cenník | F36: 45271 | G36: Beijer
A37: 36 | B37: Konzola na zem FFMINI čierna do 360 kg | C37: 89 | D37: ks | E37: cenník | F37: 45271 | G37: Beijer
A38: 37 | B38: Konzola na šikmú strechu | C38: 32 | D38: ks | E38: cenník | F38: 45344 | G38: Beijer

Sheet Cenník Powering 
A1: P.č. | B1: MATERIÁL POWERING | C1: Cenník | D1: Jednotka | E1: Zľava | F1: Dodávateľ
A2: 1 | B2: =IF($G$3>0,"Žľab 65x50 mm + tvarovky","Žľab 65x50 mm") -> Žľab 65x50 mm + tvarovky | C2: =5.74*(1+$G$3) -> 7.462 | D2: m | E2: 0.5 | F2: Powering | G2: Príplatok tvarovky
A3: 2 | B3: =IF($G$3>0,"Žľab 80x60 mm + tvarovky","Žľab 80x60 mm") -> Žľab 80x60 mm + tvarovky | C3: =6.32*(1+$G$3) -> 8.216 | D3: m | E3: 0.5 | F3: Powering | G3: =CP!M29 -> 0.3
A4: 3 | B4: =IF($G$3>0,"Žľab 90x65 mm + tvarovky","Žľab 90x65 mm") -> Žľab 90x65 mm + tvarovky | C4: =7.64*(1+$G$3) -> 9.932 | D4: m | E4: 0.5 | F4: Powering
A5: 4 | B5: Žľab 120x75 mm + tvarovky | C5: =14.92*(1+$G$3) -> 19.396 | D5: m | E5: 0.5 | F5: Powering
A6: 5 | B6: Potrubie Cu 6/10 x 0,8 Dual | C6: =4.48*2 -> 8.96 | D6: m | E6: 0.5 | F6: Powering
A7: 6 | B7: Potrubie Cu 6/12 x 0,8 Dual | C7: =5.6*2 -> 11.2 | D7: m | E7: 0.5 | F7: Powering
A8: 7 | B8: Potrubie Cu 6 x 0,8 Single | C8: =2*1.87 -> 3.74 | D8: m | E8: 0.5 | F8: Powering
A9: 8 | B9: Potrubie Cu 10 x 0,8 Single | C9: =2.78*2 -> 5.56 | D9: m | E9: 0.5 | F9: Powering
A10: 9 | B10: Potrubie Cu 12 x 0,8 Single | C10: =2*3.69 -> 7.38 | D10: m | E10: 0.5 | F10: Powering
A11: 10 | B11: Potrubie Cu 16 x 1,0 Single | C11: =6.22*2 -> 12.44 | D11: m | E11: 0.5 | F11: Powering
A12: 11 | B12: Hadica na kondenz 16 mm | C12: 0.96 | D12: m | E12: 0.5 | F12: Powering
A13: 12 | B13: Hadica na kondenz 18 mm | C13: 0.96 | D13: m | E13: 0.5 | F13: Powering
A14: 13 | B14: Hadica na kondenz 20 mm | C14: 1.08 | D14: m | E14: 0.5 | F14: Powering
A15: 14 | B15: Redukcia Y na kondenz | C15: 1.66 | D15: ks | E15: 0.5 | F15: Powering
A16: 15 | B16: Konzola 450 mm s vodováhou (80 kg) | C16: 25.66 | D16: ks | E16: 0.5 | F16: Powering
A17: 16 | B17: Konzola 450 mm s vodováhou (100 kg) | C17: 29.29 | D17: ks | E17: 0.5 | F17: Powering
A18: 17 | B18: Konzola 600 mm s vodováhou (160 kg) | C18: 44.06 | D18: ks | E18: 0.5 | F18: Powering
A19: 18 | B19: PVC podstavec 450 mm | C19: 15.78 | D19: ks | E19: 0.5 | F19: Powering
A20: 19 | B20: Podstavec z vulkanizovanej gumy 450 mm | C20: 44.54 | D20: ks | E20: 0.5 | F20: Powering
A21: 20 | B21: Podstavec z vulkanizovanej gumy 600 mm | C21: 73.78 | D21: ks | E21: 0.5 | F21: Powering
A22: 21 | B22: Silentbloky 48x20 mm set | C22: 4.8 | D22: ks | E22: 0.5 | F22: Powering
A23: 22 | B23: Káblový ovládač základný 120x120 mm + 10 m kábel | C23: 149 | D23: ks | E23: 0.5 | F23: Powering
... A40: 39 | B40: 3-cestný ventil so servopohonom | C40: 344 | D40: ks | E40: 0.5 | F40: Powering

Sheet Cenník VIVAX 
A1: P.č. | B1: VIVAX | C1: Cenník | D1: Jednotka | E1: Zľava | F1: Dodávateľ
A2: 1 | B2: Y-DESIGN | D2: ks | E2: 0.5 | F2: VIVAX | G2: Príplatok tvarovky
A3: 2 | B3: ACP-12CH35AEYIs R32 / I | C3: 1 462,10 € | D3: ks | E3: 0.5 | F3: VIVAX
A4: 3 | B4: ACP-12CH35AEYIs R32 / O | D4: ks | E4: 0.5 | F4: VIVAX
A5: 4 | B5: N-DESIGN | D5: ks | E5: 0.5 | F5: VIVAX
A6: 5 | B6: ACP-07CH21AEMI/I | C6: 216,36 € | D6: ks | E6: 0.5 | F6: VIVAX
A7: 6 | D7: ks | E7: 0.5 | F7: VIVAX
A8: 7 | B8: H+ DESIGN | D8: ks | E8: 0.5 | F8: VIVAX
A9: 8 | B9: Vnútorná | C9: (vrátane RP) | D9: ks | E9: 0.5 | F9: VIVAX
A10: 9 | B10: ACP-12CH35AEHI+ /I WHITE | C10: 982,37 € | D10: ks | E10: 0.5 | F10: VIVAX
A11: 10 | B11: ACP-12CH35AEHI+ R32 /O | D11: ks | E11: 0.5 | F11: VIVAX
A12: 11 | B12: ACP-12CH35AEHI+ /I SILVER | C12: 1 023,70 € | D12: ks | E12: 0.5 | F12: VIVAX
A13: 12 | B13: ACP-12CH35AEHI+ R32 /O | D13: ks | E13: 0.5 | F13: VIVAX
A14: 13 | B14: ACP-12CH35AEHI+/I GOLD | C14: 1 023,70 € | D14: ks | E14: 0.5 | F14: VIVAX
A15: 14 | B15: ACP-12CH35AEHI+ R32 /O | D15: ks | E15: 0.5 | F15: VIVAX
A16: 15 | B16: ACP-12CH35AEHI+ /I MIRROR | C16: 1 072,76 € | D16: ks | E16: 0.5 | F16: VIVAX
A17: 16 | B17: ACP-12CH35AEHI+ R32 /O | D17: ks | E17: 0.5 | F17: VIVAX
A18: 17 | B18: ACP-18CH50AEHI+ /I WHITE | C18: 1 279,40 € | D18: ks | E18: 0.5 | F18: VIVAX
A19: 18 | B19: ACP-18CH50AEHI+ R32 /O | D19: ks | E19: 0.5 | F19: VIVAX
A20: 19 | B20: ACP-18CH50AEHI+ /I SILVER | C20: 1 332,71 € | D20: ks | E20: 0.5 | F20: VIVAX
A21: 20 | B21: ACP-18CH50AEHI+ R32 /O | D21: ks | E21: 0.5 | F21: VIVAX
A22: 21 | B22: ACP-18CH50AEHI+ /I GOLD | C22: 1 332,71 € | D22: ks | E22: 0.5 | F22: VIVAX
A23: 22 | B23: ACP-18CH50AEHI+ R32 /O | D23: ks | E23: 0.5 | F23: VIVAX
A24: 23 | B24: ACP-18CH50AEHI+ /I MIRROR | C24: 1 394,77 € | D24: ks | E24: 0.5 | F24: VIVAX
A25: 24 | B25: ACP-18CH50AEHI+ R32 /O | D25: ks | E25: 0.5 | F25: VIVAX
A26: 25 | D26: ks | E26: 0.5 | F26: VIVAX
A27: 26 | B27: Vnútorná / vonkajšia jednotka | D27: ks | E27: 0.5 | F27: VIVAX
A28: 27 | B28: R+ DESIGN | D28: ks | E28: 0.5 | F28: VIVAX
A29: 28 | B29: ACP-09CH25AERI+ R32 / I | C29: 732.04 | D29: ks | E29: 0.5 | F29: VIVAX
A30: 29 | B30: ACP-09CH25AERI+ / O | D30: ks | E30: 0.5 | F30: VIVAX
A31: 30 | B31: ACP-09CH25AERI+ GOLD / | C31: 764.61 | D31: ks | E31: 0.5 | F31: VIVAX
A32: 31 | B32: ACP-09CH25AERI+ / O | D32: ks | E32: 0.5 | F32: VIVAX
A33: 32 | B33: ACP-09CH25AERI+ SILVER / I | C33: 764.61 | D33: ks | E33: 0.5 | F33: VIVAX
A34: 33 | B34: ACP-09CH25AERI+ / O | D34: ks | E34: 0.5 | F34: VIVAX
A35: 34 | B35: ACP-12CH35AERI+ R32 / I | C35: 762.34 | D35: ks | E35: 0.5 | F35: VIVAX
A36: 35 | B36: ACP-12CH35AERI+ / O | D36: ks | E36: 0.5 | F36: VIVAX
A37: 36 | B37: ACP-12CH35AERI+ GOLD / I | C37: 816.3 | D37: ks | E37: 0.5 | F37: VIVAX
A38: 37 | B38: ACP-12CH35AERI+ / O | D38: ks | E38: 0.5 | F38: VIVAX
A39: 38 | B39: ACP-12CH35AERI+ SILVER / I | C39: 816.3 | D39: ks | E39: 0.5 | F39: VIVAX
A40: 39 | B40: ACP-12CH35AERI+ / O | D40: ks | E40: 0.5 | F40: VIVAX
...

Sheet Cenník Sinclair 
A1: Pč | C1: Cena | D1: Jednotka | E1: Zľava | F1: Dodávateľ
B2: SPECTRUM PLUS SET INDOOR + OUTDOOR
A3: 1 | B3: ASH-09BIS2/W Nástenná klimatizácia SET | C3: 834 | D3: ks | E3: 0.49 | F3: SINCLAIR
A4: 2 | B4: ASH-13BIS2/W Nástenná klimatizácia SET | C4: 885 | D4: ks | E4: 0.49 | F4: SINCLAIR
A5: 3 | B5: ASH-18BIS2/W Nástenná klimatizácia SET | C5: 1 121 | D5: ks | E5: 0.49 | F5: SINCLAIR
A6: 4 | B6: ASH-24BIS2/W Nástenná klimatizácia SET | C6: 1 176 | D6: ks | E6: 0.49 | F6: SINCLAIR
A7: 5 | B7: TERREL SÉRIA SET INDOOR + OUTDOOR, WHITE PANEL
A8: 6 | B8: SIH-09BITx Terrel vnútorná jednotka | C8: 161.07 | D8: ks | E8: 0.49 | F8: SINCLAIR
A9: 7 | B9: SOH-09BIT Terrel Vonkajšia jednotka | C9: 262.08 | D9: ks | E9: 0.49 | F9: SINCLAIR
A10: 8 | B10: Cena Nástenná klimatizácia Terrel SET | C10: 423.15 | D10: ks | E10: 0.49 | F10: SINCLAIR
A11: 9 | B11: SIH-13BITx Terrel vnútorná jednotk | C11: 171.99 | D11: ks | E11: 0.49 | F11: SINCLAIR
A12: 10 | B12: SOH-13BIT Terrel Vonkajšia jednotka | C12: 278.46 | D12: ks | E12: 0.49 | F12: SINCLAIR
A13: 11 | B13: Cena Nástenná klimatizácia Terrel SET | C13: 450.45 | D13: ks | E13: 0.49 | F13: SINCLAIR
A14: 12 | B14: SIH-18BIT2x Terrel vnútorná jednotka | C14: 227.5 | D14: ks | E14: 0.49 | F14: SINCLAIR
A15: 13 | B15: SOH-18BIT2 Terrel Vonkajšia jednotka | C15: 491.4 | D15: ks | E15: 0.49 | F15: SINCLAIR
A16: 14 | B16: Cena Nástenná klimatizácia Terrel SET | C16: 718.9 | D16: ks | E16: 0.49 | F16: SINCLAIR
A17: 15 | B17: SIH-24BIT2x Terrel vnútorná jednotka | C17: 268.45 | D17: ks | E17: 0.49 | F17: SINCLAIR
A18: 16 | B18: SOH-24BIT2 Terrel Vonkajšia jednotka | C18: 586.95 | D18: ks | E18: 0.49 | F18: SINCLAIR
A19: 17 | B19: Cena Nástenná klimatizácia Terrel SET | C19: 855.4 | D19: ks | E19: 0.49 | F19: SINCLAIR
A20: 18 | B20: TERREL COLOR SÉRIA SET INDOOR + OUTDOOR, x options: S = Silver, B = Black, C = Champagne
A21: 19 | B21: SIH-09BITW Terrel vnútorná jednotka | C21: 161.07 | D21: ks | E21: 0.49 | F21: SINCLAIR
A22: 20 | B22: SOH-09BIT Terrel Vonkajšia jednotka | C22: 262.08 | D22: ks | E22: 0.49 | F22: SINCLAIR
A23: 21 | B23: Cena Nástenná klimatizácia Terrel SET | C23: 423.15 | D23: ks | E23: 0.49 | F23: SINCLAIR
A24: 22 | B24: SIH-13BITW Terrel vnútorná jednotk | C24: 171.99 | D24: ks | E24: 0.49 | F24: SINCLAIR
A25: 23 | B25: SOH-13BIT Terrel Vonkajšia jednotka | C25: 278.46 | D25: ks | E25: 0.49 | F25: SINCLAIR
A26: 24 | B26: Cena Nástenná klimatizácia Terrel SET | C26: 450.45 | D26: ks | E26: 0.49 | F26: SINCLAIR
A27: 25 | B27: SIH-18BIT2W Terrel vnútorná jednotka | C27: 227.5 | D27: ks | E27: 0.49 | F27: SINCLAIR
A28: 26 | B28: SOH-18BIT2 Terrel Vonkajšia jednotka | C28: 491.4 | D28: ks | E28: 0.49 | F28: SINCLAIR
A29: 27 | B29: Cena Nástenná klimatizácia Terrel SET | C29: 718.9 | D29: ks | E29: 0.49 | F29: SINCLAIR
A30: 28 | B30: SIH-24BIT2W Terrel vnútorná jednotka | C30: 268.45 | D30: ks | E30: 0.49 | F30: SINCLAIR
A31: 29 | B31: SOH-24BIT2 Terrel Vonkajšia jednotka | C31: 586.95 | D31: ks | E31: 0.49 | F31: SINCLAIR
A32: 30 | B32: Cena Nástenná klimatizácia Terrel SET | C32: 855.4 | D32: ks | E32: 0.49 | F32: SINCLAIR
A33: 31 | B33: MARVIN SÉRIA SET INDOOR + OUTDOOR
A34: 32 | B34: SIH-09BIMW vnútorná jednotka | C34: 182 | D34: ks | E34: 0.49 | F34: SINCLAIR | K34: y
A35: 33 | B35: SOH-09BIM Vonkajšia jednotka | C35: 303.03 | D35: ks | E35: 0.49 | F35: SINCLAIR
A36: 34 | B36: Cena Nástenná klimatizácia MARVIN SET | C36: 485.03 | D36: ks | E36: 0.49 | F36: SINCLAIR
A37: 35 | B37: SIH-12BIMW vnútorná jednotka | C37: 191.1 | D37: ks | E37: 0.49 | F37: SINCLAIR
A38: 36 | B38: SOH-12BIM Vonkajšia jednotka | C38: 324.87 | D38: ks | E38: 0.49 | F38: SINCLAIR
A39: 37 | B39: Cena Nástenná klimatizácia MARVIN SET | C39: 515.97 | D39: ks | E39: 0.49 | F39: SINCLAIR
A40: 38 | B40: SIH-18BIMW vnútorná jednotka | C40: 240.24 | D40: ks | E40: 0.49 | F40: SINCLAIR
...

Sheet cenniktoshiba
A1: P.č. | B1: TOSHIBA | C1: Cenník | D1: Jednotka | E1: Zľava | F1: Dodávateľ
B2: KLIMATIZÁCIE RESIDENTIAL
A3: 1 | B3: Toshiba Seiya 07E2 Qch=2,0 kW vnútorná nástenná + vonkajšia | C3: 1210 | D3: ks | E3: 0.5 | F3: MSD Company
A4: 2 | B4: Toshiba Seiya 10E2 Qch=2,5 kW vnútorná nástenná + vonkajšia | C4: 1305 | D4: ks | E4: 0.5 | F4: MSD Company
A5: 3 | B5: Toshiba Seiya 13E2 Qch=3,5 kW vnútorná nástenná + vonkajšia | C5: 1415 | D5: ks | E5: 0.5 | F5: MSD Company
A6: 4 | B6: Toshiba Seiya 16E2 Qch=4,2 kW vnútorná nástenná + vonkajšia | C6: 1840 | D6: ks | E6: 0.5 | F6: MSD Company
A7: 5 | B7: Toshiba Seiya 18E2 Qch=5,0 kW vnútorná nástenná + vonkajšia | C7: 2195 | D7: ks | E7: 0.5 | F7: MSD Company
A8: 6 | B8: Toshiba Seiya 24E2 Qch=6,5 kW vnútorná nástenná + vonkajšia | C8: 2670 | D8: ks | E8: 0.5 | F8: MSD Company
A9: 7 | B9: Toshiba Shorai Edge 07J2 Qch=2,0 kW vnútorná nástenná + vonkajšia | C9: 1450 | D9: ks | E9: 0.5 | F9: MSD Company
A10: 8 | B10: Toshiba Shorai Edge 10J2 Qch=2,5 kW vnútorná nástenná + vonkajšia | C10: 1510 | D10: ks | E10: 0.5 | F10: MSD Company
A11: 9 | B11: Toshiba Shorai Edge 13J2 Qch=3,5 kW vnútorná nástenná + vonkajšia | C11: 1755 | D11: ks | E11: 0.5 | F11: MSD Company
A12: 10 | B12: Toshiba Shorai Edge 16J2 Qch=4,2 kW vnútorná nástenná + vonkajšia | C12: 2065 | D12: ks | E12: 0.5 | F12: MSD Company
A13: 11 | B13: Toshiba Shorai Edge 18J2 Qch=5,0 kW vnútorná nástenná + vonkajšia | C13: 2375 | D13: ks | E13: 0.5 | F13: MSD Company
A14: 12 | B14: Toshiba Shorai Edge 22J2 Qch=6,1 kW vnútorná nástenná + vonkajšia | C14: 2725 | D14: ks | E14: 0.5 | F14: MSD Company
... A35: 33 | B35: Toshiba Daisekai 9 16PK Qch=4,5 kW vnútorná nástenná + vonkajšia | C35: 3090 | D35: ks | E35: 0.5 | F35: MSD Company
A36: 34 | B36: Toshiba Seiya RAS-B07E2KVG-E vnútorná nástenná jednotka | C36: 273.6 | D36: ks | E36: 0.5 | F36: MSD Company | G36: =C36*0.8 -> 218.88
A37: 35 | B37: Toshiba Seiya RAS-B10E2KVG-E vnútorná nástenná jednotka | C37: 280.8 | D37: ks | E37: 0.5 | F37: MSD Company | G37: =C37*0.8 -> 224.64
A38: 36 | B38: Toshiba Seiya RAS-B13E2KVG-E vnútorná nástenná jednotka | C38: 288 | D38: ks | E38: 0.5 | F38: MSD Company | G38: =C38*0.8 -> 230.4
A39: 37 | B39: Toshiba Seiya RAS-B16E2KVG-E vnútorná nástenná jednotka | C39: 302.4 | D39: ks | E39: 0.5 | F39: MSD Company | G39: =C39*0.8 -> 241.92
A40: 38 | B40: Toshiba Shorai Edge RAS-B07G3KVSG-E vnútorná nástenná jednotka | C40: 496.8 | D40: ks | E40: 0.5 | F40: MSD Company
A41: 39 | B41: Toshiba Shorai Edge RAS-B10G3KVSG-E vnútorná nástenná jednotka | C41: 500.4 | D41: ks | E41: 0.5 | F41: MSD Company
A42: 40 | B42: Toshiba Shorai Edge RAS-B13G3KVSG-E vnútorná nástenná jednotka | C42: 536.4 | D42: ks | E42: 0.5 | F42: MSD Company
A43: 41 | B43: Toshiba Shorai Edge RAS-B16G3KVSG-E vnútorná nástenná jednotka | C43: 576 | D43: ks | E43: 0.5 | F43: MSD Company
A44: 42 | B44: Toshiba Shorai Edge RAS-B18G3KVSG-E vnútorná nástenná jednotka | C44: 612 | D44: ks | E44: 0.5 | F44: MSD Company
A45: 43 | B45: Toshiba Shorai Edge RAS-B22G3KVSG-E vnútorná nástenná jednotka | C45: 702 | D45: ks | E45: 0.5 | F45: MSD Company
A46: 44 | B46: Toshiba Shorai Edge RAS-B24G3KVSG-E vnútorná nástenná jednotka | C46: 820.8 | D46: ks | E46: 0.5 | F46: MSD Company
A47: 45 | B47: Toshiba Haori RAS-B10N4KVRG-E vnútorná nástenná jednotka | C47: 644.4 | D47: ks | E47: 0.5 | F47: MSD Company
A48: 46 | B48: Toshiba R32 RAS-2M14U2AVG-E 4kW vonkajšia jednotka | C48: =1917*0.8 -> 1533.6 | D48: ks | E48: 0.5 | F48: MSD Company
A49: 47 | B49: Toshiba R32 RAS-2M18U2AVG-E 5,2kW vonkajšia jednotka | C49: 1607.04 | D49: ks | E49: 0.5 | F49: MSD Company
A50: 48 | B50: Toshiba R32 RAS-3M18U2AVG-E 5,2kW vonkajšia jednotka | C50: 2185.92 | D50: ks | E50: 0.5 | F50: MSD Company
A51: 49 | B51: Toshiba R32 RAS-3M26U2AVG-E 7,5kW vonkajšia jednotka | C51: 2557.44 | D51: ks | E51: 0.5 | F51: MSD Company
A52: 50 | B52: Toshiba R32 RAS-4M27U2AVG-E 8kW vonkajšia jednotka | C52: 2950.56 | D52: ks | E52: 0.5 | F52: MSD Company
A53: 51 | B53: Toshiba R32 RAS-5M34U2AVG-E 10kW vonkajšia jednotka | C53: 3408.48 | D53: ks | E53: 0.5 | F53: MSD Company
A54: 52 | B54: Toshiba Outdoor unit, 4 kW HWT-401HW-E | C54: 1985 | D54: ks | E54: 0.5 | F54: MSD Company
A55: 53 | B55: Toshiba Outdoor unit, 6 kW HWT-601HW-E | C55: 2210 | D55: ks | E55: 0.5 | F55: MSD Company
A56: 54 | B56: Toshiba Outdoor unit, 8 kW HWT-801HW-E | C56: 3885 | D56: ks | E56: 0.5 | F56: MSD Company
A57: 55 | B57: Toshiba Outdoor unit, 8 kW, 3-phase HWT-801H8W-E | C57: 5275 | D57: ks | E57: 0.5 | F57: MSD Company
A58: 56 | B58: Toshiba Outdoor unit, 11 kW HWT-1101HW-E | C58: 4350 | D58: ks | E58: 0.5 | F58: MSD Company
A59: 57 | B59: Toshiba Outdoor unit, 11 kW, 3-phase HWT-1101H8W-E | C59: 5985 | D59: ks | E59: 0.5 | F59: MSD Company
A60: 58 | B60: Toshiba Outdoor unit, 14 kW HWT-1401HW-E | C60: 5510 | D60: ks | E60: 0.5 | F60: MSD Company
...

Sheet databáza KONTAKTY
B1: Bc. Mojmír Svoboda | C1: 421910907037 | D1: svoboda@edt.sk | F1: Servis manager
B2: Veronika Husárová | C2: 421905621661 | D2: servis.rozpocty@edt.sk
B3: Ing. Eduard Tuna | D3: etuna@edt.sk | F3: Director
B4: Ing. Matúš Derco | C4: 421911907027 | D4: derco@edt.sk | F4: Zákazkár
B5: Ing. Gejza Szabó | C5: 421915678958 | D5: szabo@edt.sk | F5: Sales manager for HVAC
B6: Ing. Andrej Majstrík | C6: 421911292442 | D6: majstrik@edt.sk | F6: Obchodný zástupca
B7: Mgr. Martin Holík | C7: 421902383121 | D7: holik@klimafresh.sk | F7: Konateľ
A9: Zákazník | B9: Kontaktná osoba | C9: t.č. | D9: e-mail | E9: adresa
A12: ABONUS s.r.o. | B12: Ing. Bohuslav Štepán | C12: 421905618689 | D12: bohuslav.stepan@abonus.com | E12: Pri strelnici 27 , Bratislava
A13: ABONUS s.r.o. | B13: Ing. Igor Silván | C13: 421905322793 | D13: igor.silvan@abonus.com | E13: Pri strelnici 27 , Bratislava
A14: ABONUS s.r.o. | B14: Jozef Sklenka | C14: 421918704637 | D14: jozef.sklenka@abonus.com | E14: Pri strelnici 27 , Bratislava
A15: ABONUS s.r.o. | B15: Jaroslav Žilavý | C15: 421905550033 | D15: jaroslav.zilavy@abonus.com | E15: Pri strelnici 27 , Bratislava
A16: Abas SR Managment | B16: Pavol Ondrovič | C16: 421910835203 | D16: facility.manager@abasco.sk | E16: Dúbravská cesta 1792/2C , Bratislava
A17: Adam Faljs | B17: Adam Flajs | C17: 421904919663 | D17: flajs.adam@gmail.com | E17: Bajkalská29E , Bratislava
A18: Adient Slovakia s.r.o. | B18: Marek Sojka | C18: 421907844094 | D18: marek.sojka@adient.com | E18: Mikušovská cesta 5363 , Lučenec | F18: JCI Lučenec
A19: Atos IT Solutions and Services s.r.o. | B19: Hudecová Dagmar | C19: 421903244640 | D19: dagmar.hudecova@atos.net | E19: Pribinova 19, Bratislava
A20: Adient Slovakia s.r.o. | B20: Julius Kantor | C20: 421918852137 | D20: julius.kantor@adient.com | E20: Mikušovská cesta 5363 , Lučenec | F20: JCI Lučenec
A21: Audiaplastics s.r.o. | B21: Radomír Telčík | C21: 421917444004 | D21: radomir.talcik@washpenn.com | E21: Voderady
A22: Audiaplastics s.r.o. | B22: Daniel Vypala | C22: 421918987821 | D22: daniel.vypala@washpenn.com | E22: Voderady
A23: Edita Aibekova | B23: p. Aibekova | C23: 421914108897 | D23: edita.aibekova@gmail.com | E23: Galanta
A24: Air Livery Limited , org.zl. | B24: Ing. Jozef Pojedinec | C24: 421905705769 | D24: pojedinec@viphandling.sk | E24: letisko M.R.Štefánika , Bratislava | F24: letisko MRŠtefánika
A25: AIRMARKET, s.r.o. | B25: Ján Mihala | C25: 421903421846 | D25: jan.mihala@gmail.com | E25: Jánošíková 2773/4A Nové Mesto nad Váhom | F25: projektant VZT
A26: AZ KLIMA SK, s.r.o | B26: Ing. Maroš Koník | C26: 421903265554 | D26: maros.konik@azklima.sk | E26: Nová Rožňavská 134/A, 831 04 Bratislava, Slovensko
A27: AZ KLIMA SK, s.r.o | B27: Radovan Knut | C27: 421903760874 | D27: radovan.knut@azklima.sk | E27: Nová Rožňavská 134/A, 831 04 Bratislava, Slovensko | F27: vedúci servisu
A28: BDI spol.s.r.o. | B28: Ing. Denisa Balkovská | C28: 421455240521 | D28: denisa.balkovska@dbi.sk | E28: T.G.Masaryka 9445/19, Zvolen
A29: BH ESTATE s.r.o. | B29: Jaroslav Haluška | C29: 33620030711 | D29: jlhcfr@gmail.com | E29: Landererova 6 , BA
A30: BILLA | B30: Ing. Ladislav Paško | C30: 421911067482 | D30: l.pasko@billa.sk | E30: Bajkalská 19/A , Bratislava
A31: BOCK SR s.r.o. | B31: Silvia Gelienová | C31: 421907707347 | D31: priprava@bocksr.sk | E31: Mostná 72, Nitra
A32: Cestné stavby Liptovský Mikuláš spol. s r.o. | B32: Tatiana Oravcová | C32: 421903400636 | D32: oravcova@cestnestavbylm.sk | E32: Ul. 1. mája 724, 031 01 Liptovský Mikuláš
A33: CRH Slovensko a.s. | B33: Ing. Aleš Pláteník | C33: 421903844588 | D33: ales.platenik@sk.crh.com | E33: Rohožník / Slovakia
A34: CRH Slovensko a.s. | B34: Dušan Rečný | C34: 421903269324 | D34: dusan.recny@sk.crh.com | E34: Rohožník / Slovakia
A35: CRH Slovensko a.s. | B35: Lubomír Ukropec | C35: 421903554622 | D35: lubomir.ukropec@sk.crh.com | E35: Rohožník / Slovakia
A36: CRH Slovensko a.s. | B36: Milan Fašánek | C36: 421903554676 | D36: milan.fasanek@sk.crh.com | E36: Rohožník / Slovakia
A37: CRH Slovensko a.s. | B37: Andrej Galbička | C37: 421902463365 | D37: andrej.galbicka@sk.crh.com | E37: Rohožník / Slovakia
A38: CRH Slovensko a.s. | B38: Tomáš Kainz | D38: tomas.kainz@sk.crh.com | E38: Rohožník / Slovakia
A39: Commerc service spol.s.r.o. | B39: Ľubica Surgentová | C39: 421517724344 | D39: loziska@commercservice.sk | E39: ku Surdoku 35 , 08001 Prešov | F39: Getragford správcovská
A40: Roman Dóza | B40: Roman Dóza | C40: 421904176107 | D40: dozaroman.mobil@gmail.com | E40: Stavbárska 40, Bratislava
A41: Spoločnosť Čínska reštaurácia, s.r.o. | B41: Ji | C41: 421902700628 | D41: info@cina-kuchajda.sk | E41: Tomašikova 55, Bratislava
A42: Deltech a.s. | B42: Ivan Šeucovič | C42: 421911889147 | D42: ivan.seucovic@deltech.sk | E42: Priemyselná 1, 031 01 Liptovský Mikuláš
A43: DSS Integra | B43: PaedDr. Renáta Balážová | C43: 421918826517 | D43: riaditel@dssintegra.sk | E43: Tylová 21, 831 04 Bratislava
...

Sheet Cenník Mitsubishi
A1: P.č. | B1: MITSUBISHI | C1: Cenník | D1: Jednotka | E1: Zľava | F1: Dodávateľ
B2: KLIMATIZÁCIE RESIDENTIAL
A3: 1 | B3: Mitsubishi Economy HR25 Qch=2,5 kW vnútorná nástenná + vonkajšia | C3: 820 | D3: ks | E3: 0.39 | F3: CS-Mtrade
A4: 2 | B4: Mitsubishi Economy HR35 Qch=3,5 kW vnútorná nástenná + vonkajšia | C4: 944 | D4: ks | E4: 0.39 | F4: CS-Mtrade
A5: 3 | B5: Mitsubishi Economy HR35 Qch=5,0 kW vnútorná nástenná + vonkajšia | C5: 1228 | D5: ks | E5: 0.39 | F5: CS-Mtrade
A6: 4 | B6: Mitsubishi Standard AP20 Qch=2,0 kW vnútorná nástenná + vonkajšia | C6: 1237 | D6: ks | E6: 0.39 | F6: CS-Mtrade
A7: 5 | B7: Mitsubishi Standard AY25 Qch=2,5 kW vnútorná nástenná + vonkajšia | C7: 1304 | D7: ks | E7: 0.39 | F7: CS-Mtrade
A8: 6 | B8: Mitsubishi Standard AY35 Qch=3,5 kW vnútorná nástenná + vonkajšia | C8: 1502 | D8: ks | E8: 0.39 | F8: CS-Mtrade
A9: 7 | B9: Mitsubishi Standard AY42 Qch=4,2 kW vnútorná nástenná + vonkajšia | C9: 1590 | D9: ks | E9: 0.39 | F9: CS-Mtrade
A10: 8 | B10: Mitsubishi Standard AY50 Qch=5,0 kW vnútorná nástenná + vonkajšia | C10: 1704 | D10: ks | E10: 0.39 | F10: CS-Mtrade
A11: 9 | B11: Mitsubishi Standard AP60 Qch=6,1 kW vnútorná nástenná + vonkajšia | C11: 1929 | D11: ks | E11: 0.39 | F11: CS-Mtrade
A12: 10 | B12: Mitsubishi Standard AP70 Qch=7,1 kW vnútorná nástenná + vonkajšia | C12: 2369 | D12: ks | E12: 0.39 | F12: CS-Mtrade
A13: 11 | B13: Mitsubishi Premium EF25 Qch=2,5 kW vnútorná nástenná biela + vonkajšia | C13: 1547 | D13: ks | E13: 0.39 | F13: CS-Mtrade
A14: 12 | B14: Mitsubishi Premium EF35 Qch=3,5 kW vnútorná nástenná biela + vonkajšia | C14: 1842 | D14: ks | E14: 0.39 | F14: CS-Mtrade
... A40: 38 | B40: Mitsubishi Diamond LN60 Qch=6,1 kW vnútorná nástenná prírodná biela + vonkajšia | C40: 3156 | D40: ks | E40: 0.39 | F40: CS-Mtrade

Sheet vivax
A1: Stĺpec1 | B1: Stĺpec2 | C1: Stĺpec3 | D1: Stĺpec4 | E1: Stĺpec5 | F1: Stĺpec6
A2: P.č. | B2: VIVAX | C2: Cenník | D2: Jednotka | E2: Zľava | F2: Dodávateľ
A3: 1 | B3: Y-DESIGN | D3: ks | E3: 0.5 | F3: VIVAX
A4: 2 | B4: ACP-12CH35AEYIs R32 / I | C4: 1 462,10 € | D4: ks | E4: 0.5 | F4: VIVAX
A5: 3 | B5: ACP-12CH35AEYIs R32 / O | D5: ks | E5: 0.5 | F5: VIVAX
A6: 4 | B6: N-DESIGN | D6: ks | E6: 0.5 | F6: VIVAX
A7: 5 | B7: ACP-07CH21AEMI/I | C7: 216,36 € | D7: ks | E7: 0.5 | F7: VIVAX
A8: 6 | D8: ks | E8: 0.5 | F8: VIVAX
A9: 7 | B9: H+ DESIGN | D9: ks | E9: 0.5 | F9: VIVAX
A10: 8 | B10: Vnútorná | C10: (vrátane RP) | D10: ks | E10: 0.5 | F10: VIVAX
A11: 9 | B11: ACP-12CH35AEHI+ /I WHITE | C11: 982,37 € | D11: ks | E11: 0.5 | F11: VIVAX
A12: 10 | B12: ACP-12CH35AEHI+ R32 /O | D12: ks | E12: 0.5 | F12: VIVAX
A13: 11 | B13: ACP-12CH35AEHI+ /I SILVER | C13: 1 023,70 € | D13: ks | E13: 0.5 | F13: VIVAX
A14: 12 | B14: ACP-12CH35AEHI+ R32 /O | D14: ks | E14: 0.5 | F14: VIVAX
A15: 13 | B15: ACP-12CH35AEHI+/I GOLD | C15: 1 023,70 € | D15: ks | E15: 0.5 | F15: VIVAX
A16: 14 | B16: ACP-12CH35AEHI+ R32 /O | D16: ks | E16: 0.5 | F16: VIVAX
A17: 15 | B17: ACP-12CH35AEHI+ /I MIRROR | C17: 1 072,76 € | D17: ks | E17: 0.5 | F17: VIVAX
A18: 16 | B18: ACP-12CH35AEHI+ R32 /O | D18: ks | E18: 0.5 | F18: VIVAX
A19: 17 | B19: ACP-18CH50AEHI+ /I WHITE | C19: 1 279,40 € | D19: ks | E19: 0.5 | F19: VIVAX
A20: 18 | B20: ACP-18CH50AEHI+ R32 /O | D20: ks | E20: 0.5 | F20: VIVAX
A21: 19 | B21: ACP-18CH50AEHI+ /I SILVER | C21: 1 332,71 € | D21: ks | E21: 0.5 | F21: VIVAX
A22: 20 | B22: ACP-18CH50AEHI+ R32 /O | D22: ks | E22: 0.5 | F22: VIVAX
A23: 21 | B23: ACP-18CH50AEHI+ /I GOLD | C23: 1 332,71 € | D23: ks | E23: 0.5 | F23: VIVAX
A24: 22 | B24: ACP-18CH50AEHI+ R32 /O | D24: ks | E24: 0.5 | F24: VIVAX
A25: 23 | B25: ACP-18CH50AEHI+ /I MIRROR | C25: 1 394,77 € | D25: ks | E25: 0.5 | F25: VIVAX
A26: 24 | B26: ACP-18CH50AEHI+ R32 /O | D26: ks | E26: 0.5 | F26: VIVAX
A27: 25 | D27: ks | E27: 0.5 | F27: VIVAX
A28: 26 | B28: Vnútorná / vonkajšia jednotka | D28: ks | E28: 0.5 | F28: VIVAX
A29: 27 | B29: R+ DESIGN | D29: ks | E29: 0.5 | F29: VIVAX
A30: 28 | B30: ACP-09CH25AERI+ R32 / I | C30: 732.04 | D30: ks | E30: 0.5 | F30: VIVAX
A31: 29 | B31: ACP-09CH25AERI+ / O | D31: ks | E31: 0.5 | F31: VIVAX
A32: 30 | B32: ACP-09CH25AERI+ GOLD / | C32: 764.61 | D32: ks | E32: 0.5 | F32: VIVAX
A33: 31 | B33: ACP-09CH25AERI+ / O | D33: ks | E33: 0.5 | F33: VIVAX
A34: 32 | B34: ACP-09CH25AERI+ SILVER / I | C34: 764.61 | D34: ks | E34: 0.5 | F34: VIVAX
A35: 33 | B35: ACP-09CH25AERI+ / O | D35: ks | E35: 0.5 | F35: VIVAX
A36: 34 | B36: ACP-12CH35AERI+ R32 / I | C36: 762.34 | D36: ks | E36: 0.5 | F36: VIVAX
A37: 35 | B37: ACP-12CH35AERI+ / O | D37: ks | E37: 0.5 | F37: VIVAX
A38: 36 | B38: ACP-12CH35AERI+ GOLD / I | C38: 816.3 | D38: ks | E38: 0.5 | F38: VIVAX
A39: 37 | B39: ACP-12CH35AERI+ / O | D39: ks | E39: 0.5 | F39: VIVAX
A40: 38 | B40: ACP-12CH35AERI+ SILVER / I | C40: 816.3 | D40: ks | E40: 0.5 | F40: VIVAX
...

Sheet Table_2
A1: Column1 | B1: Column2 | C1: Column3 | D1: Column4 | E1: Column5 | F1: Column6 | G1: Column7 | H1: Column8 | I1: Column9 | J1: Column10 | K1: Column11 | L1: Column12 | M1: Column13 | N1: Column14 | O1: Column15 | P1: Column16 | Q1: Column17 | R1: Column18 | S1: Column19 | T1: Column20 | U1: Column21 | V1: Column22 | W1: Column23 | X1: Column24 | Y1: Column25 | Z1: Column26 | AA1: Column27 | AB1: Column28 | AC1: Column29 | AD1: Column30 | AE1: Column31 | AF1: Column32 | AG1: Column33 | AH1: Column34 | AI1: Column35 | AJ1: Column36 | AK1: Column37 | AL1: Column38 | AM1: Column39 | AN1: Column40 | AO1: Column41 | AP1: Column42 | AQ1: Column43 | AR1: Column44 | AS1: Column45 | AT1: Column46 | AU1: Column47 | AV1: Column48 | AW1: Column49 | AX1: Column50 | AY1: Column51 | AZ1: Column52 | BA1: Column53 | BB1: Column54 | BC1: Column55 | BD1: Column56 | BE1: Column57 | BF1: Column58 | BG1: Column59 | BH1: Column60 | BI1: Column61 | BJ1: Column62 | BK1: Column63 | BL1: Column64 | BM1: Column65 | BN1: Column66 | BO1: Column67 | BP1: Column68 | BQ1: Column69 | BR1: Column70 | BS1: Column71 | BT1: Column72 | BU1: Column73 | BV1: Column74 | BW1: Column75 | BX1: Column76 | BY1: Column77 | BZ1: Column78 | CA1: Column79 | CB1: Column80 | CC1: Column81 | CD1: Column82 | CE1: Column83 | CF1: Column84 | CG1: Column85 | CH1: Column86 | CI1: Column87 | CJ1: Column88 | CK1: Column89 | CL1: Column90 | CM1: Column91 | CN1: Column92 | CO1: Column93 | CP1: Column94 | CQ1: Column95 | CR1: Column96 | CS1: Column97 | CT1: Column98 | CU1: Column99 | CV1: Column100 | CW1: Column101 | CX1: Column102 | CY1: Column103 | CZ1: Column104 | DA1: Column105 | DB1: Column106 | DC1: Column107 | DD1: Column108 | DE1: Column109 | DF1: Column110 | DG1: Column111 | DH1: Column112 | DI1: Column113 | DJ1: Column114 | DK1: Column115 | DL1: Column116 | DM1: Column117 | DN1: Column118 | DO1: Column119 | DP1: Column120
A3: Cenník montážneho materiálu Platný od 1.4.2024
V4: Skl.číslo | AB4: Sklad | AH4: Popis | BS4: M.j. | BU4: Nákupná cena v EUR bez DPH
AH5: Predizolované medené potrubie
A6: 2000 | AB6: s | AH6: Cu potrubie predizolované 6 (1/4" x 0,8) 50m | BS6: m | BU6: 1.91
A7: 2002 | AB7: s | AH7: Cu potrubie predizolované 10 (3/8" x 0,8) 50m | BS7: m | BU7: 2.54
A8: 2004 | AB8: s | AH8: Cu potrubie predizolované 12 (1/2" x 0,8) 50m | BS8: m | BU8: 4.15
A9: 2001 | AB9: o | AH9: Cu potrubie predizolované 6 (1/4" x 1) 50m | BS9: m | BU9: 2.29
A10: 2003 | AB10: o | AH10: Cu potrubie predizolované 10 (3/8" x 1) 50m | BS10: m | BU10: 3.25
A11: 2005 | AB11: o | AH11: Cu potrubie predizolované 12 (1/2" x 1) 50m | BS11: m | BU11: 5.89
A12: 2006 | AB12: s | AH12: Cu potrubie predizolované 16 (5/8" x 1,0)50m | BS12: m | BU12: 6.35
A13: 2007 | AB13: s | AH13: Cu potrubie predizolované 18 (3/4" x 1,0) 25m | BS13: m | BU13: 8.38
A14: 2008 | AB14: s | AH14: Cu potrubie predizolované 22 (7/8" x 1,0) 25m | BS14: m | BU14: 9.21
AH15: Predizolovaná dvojica medeného potrubia (DUAL)
A16: 2010 | AB16: s | AH16: Cu potrubie predizolované DUO 6+10 (1/4"+3/8"x0,8) 25m | BS16: m | BU16: 4.2
A17: 2011 | AB17: s | AH17: Cu potrubie predizolované DUO 6+12 (1/4"+1/2"x0,8) 25m | BS17: m | BU17: 5.36
A18: 2012 | AB18: s | AH18: Cu potrubie predizolované DUO 10-16 (3/8"x5/8") 25m | BS18: m | BU18: 8.95
A19: 2013 | AB19: o | AH19: Cu potrubie predizolované DUO 6+10 (1/4"+3/8"x1) 25m | BS19: m | BU19: 6.39
A20: 2014 | AB20: o | AH20: Cu potrubie predizolované DUO 6+12 (1/4"+1/2"x1) 25m | BS20: m | BU20: 7.34
AH21: Predizolovaná dvojica medeného potrubia (DUAL - UV Resistant)
A22: 201430 | AB22: s | AH22: Cu potrubie predizolované DUO 6+10 (1/4"+3/8"x0,8) 25m | BS22: m | BU22: 4.44
A23: 201431 | AB23: s | AH23: Cu potrubie predizolované DUO 6+12 (1/4"+1/2"x0,8) 25m | BS23: m | BU23: 5.49
AH24: Izolačné pásky
A25: 2015 | AB25: s | AH25: Samolepiaca izolačná páska - čierna | BS25: ks | BU25: 7.8
A26: 2016 | AB26: s | AH26: Samolepiaca izolačná páska -biela | BS26: ks | BU26: 13.4
A27: 2017 | AB27: s | AH27: Al páska, hliníková 50mm x 50m | BS27: ks | BU27: 5.7
A28: 2018 | AB28: s | AH28: Al páska, hliníková 75mm x 50m | BS28: ks | BU28: 8.8
AH29: Čistiace a dezinfekčné prostriedky
A30: 5001 | AB30: s | AH30: RTU Evaporator 1l , čistiaci a dezinfekčný roztok výparníka | BS30: ks | BU30: 21.8
A31: 5002 | AB31: s | AH31: RTU Evaporator 5l , čistiaci a dezinfekčný roztok výparníka | BS31: ks | BU31: 24.6
A32: 5004 | AB32: s | AH32: CondenCide 5l, koncentrát - čistič výparníka s dezinfekcia | BS32: ks | BU32: 42.2
A33: 5017 | AB33: s | AH33: SuperClean 5l, koncentrát pre veľmi znečistené kondenzátory | BS33: ks | BU33: 86.9
A34: 5008 | AB34: s | AH34: Easy Care sprej-čistič a desinfekcia výparníka | BS34: ks | BU34: 14.1
A35: 5015 | AB35: s | AH35: Ulith - detekčná pena - sprej | BS35: ks | BU35: 2.8
A36: 5016 | AB36: o | AH36: Rothenberger - Sanifresh - čistič a dezinfekcia | BS36: ks | BU36: 15.9
AH37: Konzoly
A38: 6011 | AB38: s | AH38: Konzola biela - 465 | BS38: set | BU38: 18
A39: 6002 | AB39: s | AH39: Konzola biela - 550 | BS39: set | BU39: 20
A40: 6003 | AB40: s | AH40: Konzola biela - 620 | BS40: set | BU40: 28
A41: 6004 | AB41: s | AH41: Konzola biela - 700 | BS41: set | BU41: 44
...

Sheet Hárok2
A1: Dátum | B1: Meno Zákazníka | C1: Telefónne číslo | D1: Platba | E1: Druh Zásahu | F1: Platba_partner | G1: Suma | H1: PODIEL KLIMAZONE | I1: PODIEL KLIMAFRESH | J1: KOMENTY | K1: Iné info | L1: Adresa | M1: Mesiac | N1: Kategória
A2: 45298 | B2: De Paul Miko | C2: 421903250175 | D2: faktura | E2: Montaz | F2: faktura | G2: 280 | I2: 200 | J2: zistit | L2: Muskatova 20, Jur | M2: 2024-01 | N2: Iné
A3: 45298 | B3: Rudolf Herenyi | D3: neznáme | E3: Servis 2+1 | F3: faktura | I3: 74 | J3: pan chce chladivo doplnit do 4 jednotiek minimalne do 2x - cena za plnenie je 100eur na jednotku | L3: neznáme | M3: 2024-01 | N3: Servis
A4: 45298 | B4: Marek Bican | D4: neznáme | E4: Servis 2+1 | F4: hotovost | G4: 150 | I4: 74 | L4: neznáme | M4: 2024-01 | N4: Servis
A5: 45298 | B5: Jozef Stuska | C5: 421915158267 | D5: neznáme | E5: nic | F5: nic | I5: 30 | L5: neznáme | M5: 2024-01 | N5: Iné
A6: 45298 | B6: Stubna S | C6: 421918737666 | D6: neznáme | E6: Servis 2+1 | F6: hotovost | G6: 160 | H6: 80 | I6: 74 | L6: neznáme | M6: 2024-01 | N6: Servis
A7: 45298 | B7: Svetlana Durisova | C7: 421905745264 | D7: neznáme | E7: Servis 4+1 | F7: fa | I7: 140 | L7: neznáme | M7: 2024-01 | N7: Servis
A8: 45298 | B8: Lavicanova | C8: ++421911105075 , ++421904252612 | D8: neznáme | E8: Servis 2+1 | F8: hotovost | G8: 150 | H8: 76 | I8: 74 | L8: neznáme | M8: 2024-01 | N8: Servis
A9: 45298 | B9: Pavla Krauspe | C9: 421948461110 | D9: neznáme | E9: Servis 1+1 | F9: hotovost | G9: 80 | I9: 40 | L9: neznáme | M9: 2024-01 | N9: Servis
A10: 45329 | B10: Petra Adams | C10: 421902705618 | D10: neznáme | E10: Servis 2+1 | F10: hotovost | G10: 170 | H10: 90 | I10: 74 | L10: neznáme | M10: 2024-02 | N10: Servis
